Failure # 1 (occurred at 2020-11-22_16-08-49)
Traceback (most recent call last):
  File "/home/avandekl/miniconda3/lib/python3.8/site-packages/ray/tune/trial_runner.py", line 726, in _process_trial
    result = self.trial_executor.fetch_result(trial)
  File "/home/avandekl/miniconda3/lib/python3.8/site-packages/ray/tune/ray_trial_executor.py", line 489, in fetch_result
    result = ray.get(trial_future[0], timeout=DEFAULT_GET_TIMEOUT)
  File "/home/avandekl/miniconda3/lib/python3.8/site-packages/ray/worker.py", line 1452, in get
    raise value.as_instanceof_cause()
ray.exceptions.RayTaskError(TuneError): [36mray::ImplicitFunc.train()[39m (pid=27080, ip=10.32.116.100)
  File "python/ray/_raylet.pyx", line 482, in ray._raylet.execute_task
  File "python/ray/_raylet.pyx", line 436, in ray._raylet.execute_task.function_executor
  File "/home/avandekl/miniconda3/lib/python3.8/site-packages/ray/tune/trainable.py", line 336, in train
    result = self.step()
  File "/home/avandekl/miniconda3/lib/python3.8/site-packages/ray/tune/function_runner.py", line 366, in step
    self._report_thread_runner_error(block=True)
  File "/home/avandekl/miniconda3/lib/python3.8/site-packages/ray/tune/function_runner.py", line 512, in _report_thread_runner_error
    raise TuneError(("Trial raised an exception. Traceback:\n{}"
ray.tune.error.TuneError: Trial raised an exception. Traceback:
[36mray::ImplicitFunc.train()[39m (pid=27080, ip=10.32.116.100)
  File "/home/avandekl/miniconda3/lib/python3.8/site-packages/ray/tune/function_runner.py", line 248, in run
    self._entrypoint()
  File "/home/avandekl/miniconda3/lib/python3.8/site-packages/ray/tune/function_runner.py", line 315, in entrypoint
    return self._trainable_func(self.config, self._status_reporter,
  File "/home/avandekl/miniconda3/lib/python3.8/site-packages/ray/tune/function_runner.py", line 575, in _trainable_func
    output = fn()
  File "run.py", line 7, in trainable
    train.Experiment(**config['experiment_config']).train(**config['train_config'])
  File "/home/avandekl/Documents/thesis/train.py", line 186, in train
    next_obs_dict, reward, done, info = self.env.step(action)
  File "/home/avandekl/Documents/thesis/wrappers.py", line 68, in step
    reward = self.compute_reward(
  File "/home/avandekl/Documents/thesis/wrappers.py", line 85, in compute_reward
    latent_achieved_goal = self._to_latent(achieved_goal)
  File "/home/avandekl/Documents/thesis/wrappers.py", line 78, in _to_latent
    latent = self.encoder.forward_single_observation(observation)
  File "/home/avandekl/Documents/thesis/agent.py", line 57, in forward_single_observation
    observation = self.conv(observation)
  File "/home/avandekl/miniconda3/lib/python3.8/site-packages/torch/nn/modules/module.py", line 727, in _call_impl
    result = self.forward(*input, **kwargs)
  File "/home/avandekl/miniconda3/lib/python3.8/site-packages/torch/nn/modules/container.py", line 117, in forward
    input = module(input)
  File "/home/avandekl/miniconda3/lib/python3.8/site-packages/torch/nn/modules/module.py", line 727, in _call_impl
    result = self.forward(*input, **kwargs)
  File "/home/avandekl/miniconda3/lib/python3.8/site-packages/torch/nn/modules/conv.py", line 423, in forward
    return self._conv_forward(input, self.weight)
  File "/home/avandekl/miniconda3/lib/python3.8/site-packages/torch/nn/modules/conv.py", line 419, in _conv_forward
    return F.conv2d(input, weight, self.bias, self.stride,
RuntimeError: expected scalar type Double but found Float

