Failure # 1 (occurred at 2020-11-23_11-33-37)
Traceback (most recent call last):
  File "/home/avandekl/miniconda3/lib/python3.8/site-packages/ray/tune/trial_runner.py", line 726, in _process_trial
    result = self.trial_executor.fetch_result(trial)
  File "/home/avandekl/miniconda3/lib/python3.8/site-packages/ray/tune/ray_trial_executor.py", line 489, in fetch_result
    result = ray.get(trial_future[0], timeout=DEFAULT_GET_TIMEOUT)
  File "/home/avandekl/miniconda3/lib/python3.8/site-packages/ray/worker.py", line 1452, in get
    raise value.as_instanceof_cause()
ray.exceptions.RayTaskError(TuneError): [36mray::ImplicitFunc.train()[39m (pid=12870, ip=10.32.116.100)
  File "python/ray/_raylet.pyx", line 482, in ray._raylet.execute_task
  File "python/ray/_raylet.pyx", line 436, in ray._raylet.execute_task.function_executor
  File "/home/avandekl/miniconda3/lib/python3.8/site-packages/ray/tune/trainable.py", line 336, in train
    result = self.step()
  File "/home/avandekl/miniconda3/lib/python3.8/site-packages/ray/tune/function_runner.py", line 366, in step
    self._report_thread_runner_error(block=True)
  File "/home/avandekl/miniconda3/lib/python3.8/site-packages/ray/tune/function_runner.py", line 512, in _report_thread_runner_error
    raise TuneError(("Trial raised an exception. Traceback:\n{}"
ray.tune.error.TuneError: Trial raised an exception. Traceback:
[36mray::ImplicitFunc.train()[39m (pid=12870, ip=10.32.116.100)
  File "/home/avandekl/miniconda3/lib/python3.8/site-packages/ray/tune/function_runner.py", line 248, in run
    self._entrypoint()
  File "/home/avandekl/miniconda3/lib/python3.8/site-packages/ray/tune/function_runner.py", line 315, in entrypoint
    return self._trainable_func(self.config, self._status_reporter,
  File "/home/avandekl/miniconda3/lib/python3.8/site-packages/ray/tune/function_runner.py", line 575, in _trainable_func
    output = fn()
  File "run.py", line 7, in trainable
    train.Experiment(**config['experiment_config']).train(**config['train_config'])
  File "/home/avandekl/Documents/thesis/train.py", line 186, in train
    next_obs_dict, reward, done, info = self.env.step(action)
  File "/home/avandekl/Documents/thesis/wrappers.py", line 67, in step
    obs_dict, reward, done, info = self.env.step(action)
  File "/home/avandekl/Documents/thesis/wrappers.py", line 238, in step
    obs, reward, done, info = self.env.step(action)
  File "/home/avandekl/Documents/thesis/wrappers.py", line 159, in step
    obs_dict, rew, done, info = self.env.step(act)
  File "/home/avandekl/miniconda3/lib/python3.8/site-packages/gym/core.py", line 234, in step
    return self.env.step(action)
  File "/home/avandekl/miniconda3/lib/python3.8/site-packages/gym/wrappers/time_limit.py", line 16, in step
    observation, reward, done, info = self.env.step(action)
  File "/home/avandekl/Documents/thesis/kinova.py", line 108, in step
    self.base.ExecuteAction(action)
  File "/home/avandekl/miniconda3/lib/python3.8/site-packages/kortex_api/autogen/client_stubs/BaseClientRpc.py", line 679, in ExecuteAction
    result = future.result(options.getTimeoutInSecond())
  File "/home/avandekl/miniconda3/lib/python3.8/concurrent/futures/_base.py", line 439, in result
    return self.__get_result()
  File "/home/avandekl/miniconda3/lib/python3.8/concurrent/futures/_base.py", line 388, in __get_result
    raise self._exception
kortex_api.Exceptions.KServerException.KServerException: Server error name=ERROR_DEVICE, sub name=SESSION_NOT_IN_CONTROL => Failed to execute action: Session not in control

