Failure # 1 (occurred at 2020-11-17_16-22-15)
Traceback (most recent call last):
  File "/home/avandekl/miniconda3/lib/python3.8/site-packages/ray/tune/trial_runner.py", line 726, in _process_trial
    result = self.trial_executor.fetch_result(trial)
  File "/home/avandekl/miniconda3/lib/python3.8/site-packages/ray/tune/ray_trial_executor.py", line 489, in fetch_result
    result = ray.get(trial_future[0], timeout=DEFAULT_GET_TIMEOUT)
  File "/home/avandekl/miniconda3/lib/python3.8/site-packages/ray/worker.py", line 1452, in get
    raise value.as_instanceof_cause()
ray.exceptions.RayTaskError(TuneError): [36mray::ImplicitFunc.train()[39m (pid=8783, ip=10.32.116.100)
  File "python/ray/_raylet.pyx", line 482, in ray._raylet.execute_task
  File "python/ray/_raylet.pyx", line 436, in ray._raylet.execute_task.function_executor
  File "/home/avandekl/miniconda3/lib/python3.8/site-packages/ray/tune/trainable.py", line 336, in train
    result = self.step()
  File "/home/avandekl/miniconda3/lib/python3.8/site-packages/ray/tune/function_runner.py", line 366, in step
    self._report_thread_runner_error(block=True)
  File "/home/avandekl/miniconda3/lib/python3.8/site-packages/ray/tune/function_runner.py", line 512, in _report_thread_runner_error
    raise TuneError(("Trial raised an exception. Traceback:\n{}"
ray.tune.error.TuneError: Trial raised an exception. Traceback:
[36mray::ImplicitFunc.train()[39m (pid=8783, ip=10.32.116.100)
  File "/home/avandekl/miniconda3/lib/python3.8/site-packages/ray/tune/function_runner.py", line 248, in run
    self._entrypoint()
  File "/home/avandekl/miniconda3/lib/python3.8/site-packages/ray/tune/function_runner.py", line 315, in entrypoint
    return self._trainable_func(self.config, self._status_reporter,
  File "/home/avandekl/miniconda3/lib/python3.8/site-packages/ray/tune/function_runner.py", line 575, in _trainable_func
    output = fn()
  File "run.py", line 7, in trainable
    train.Experiment(**config['experiment_config']).train(**config['train_config'])
  File "/home/avandekl/Documents/thesis/train.py", line 169, in train
    obs_dict = self.env.reset()
  File "/home/avandekl/miniconda3/lib/python3.8/site-packages/gym/core.py", line 237, in reset
    return self.env.reset(**kwargs)
  File "/home/avandekl/miniconda3/lib/python3.8/site-packages/gym/core.py", line 237, in reset
    return self.env.reset(**kwargs)
  File "/home/avandekl/miniconda3/lib/python3.8/site-packages/gym/wrappers/time_limit.py", line 25, in reset
    return self.env.reset(**kwargs)
  File "/home/avandekl/Documents/thesis/kinova.py", line 115, in reset
    self._set_to_home()
  File "/home/avandekl/Documents/thesis/kinova.py", line 183, in _set_to_home
    self.base.Unsubscribe(notification_handle)
  File "/home/avandekl/miniconda3/lib/python3.8/site-packages/kortex_api/autogen/client_stubs/BaseClientRpc.py", line 872, in Unsubscribe
    result = future.result(options.getTimeoutInSecond())
  File "/home/avandekl/miniconda3/lib/python3.8/concurrent/futures/_base.py", line 441, in result
    raise TimeoutError()
concurrent.futures._base.TimeoutError

