Failure # 1 (occurred at 2020-11-18_11-22-27)
Traceback (most recent call last):
  File "/home/avandekl/miniconda3/lib/python3.8/site-packages/ray/tune/trial_runner.py", line 726, in _process_trial
    result = self.trial_executor.fetch_result(trial)
  File "/home/avandekl/miniconda3/lib/python3.8/site-packages/ray/tune/ray_trial_executor.py", line 489, in fetch_result
    result = ray.get(trial_future[0], timeout=DEFAULT_GET_TIMEOUT)
  File "/home/avandekl/miniconda3/lib/python3.8/site-packages/ray/worker.py", line 1452, in get
    raise value.as_instanceof_cause()
ray.exceptions.RayTaskError(TuneError): [36mray::ImplicitFunc.train()[39m (pid=18046, ip=10.32.116.100)
  File "python/ray/_raylet.pyx", line 482, in ray._raylet.execute_task
  File "python/ray/_raylet.pyx", line 436, in ray._raylet.execute_task.function_executor
  File "/home/avandekl/miniconda3/lib/python3.8/site-packages/ray/tune/trainable.py", line 336, in train
    result = self.step()
  File "/home/avandekl/miniconda3/lib/python3.8/site-packages/ray/tune/function_runner.py", line 366, in step
    self._report_thread_runner_error(block=True)
  File "/home/avandekl/miniconda3/lib/python3.8/site-packages/ray/tune/function_runner.py", line 512, in _report_thread_runner_error
    raise TuneError(("Trial raised an exception. Traceback:\n{}"
ray.tune.error.TuneError: Trial raised an exception. Traceback:
[36mray::ImplicitFunc.train()[39m (pid=18046, ip=10.32.116.100)
  File "/home/avandekl/miniconda3/lib/python3.8/site-packages/ray/tune/function_runner.py", line 248, in run
    self._entrypoint()
  File "/home/avandekl/miniconda3/lib/python3.8/site-packages/ray/tune/function_runner.py", line 315, in entrypoint
    return self._trainable_func(self.config, self._status_reporter,
  File "/home/avandekl/miniconda3/lib/python3.8/site-packages/ray/tune/function_runner.py", line 575, in _trainable_func
    output = fn()
  File "run.py", line 7, in trainable
    train.Experiment(**config['experiment_config']).train(**config['train_config'])
  File "/home/avandekl/Documents/thesis/train.py", line 70, in __init__
    self.env = wrappers.KinovaWrapper(self.env, seed, fix_goals)
  File "/home/avandekl/Documents/thesis/wrappers.py", line 13, in KinovaWrapper
    env = ImageEnv(env) # record images
  File "/home/avandekl/Documents/thesis/wrappers.py", line 146, in __init__
    self.reset()
  File "/home/avandekl/Documents/thesis/wrappers.py", line 150, in reset
    initial_state = self.env.sim.get_state()
  File "/home/avandekl/miniconda3/lib/python3.8/site-packages/gym/core.py", line 223, in __getattr__
    return getattr(self.env, name)
  File "/home/avandekl/miniconda3/lib/python3.8/site-packages/gym/core.py", line 223, in __getattr__
    return getattr(self.env, name)
  File "/home/avandekl/miniconda3/lib/python3.8/site-packages/gym/core.py", line 223, in __getattr__
    return getattr(self.env, name)
AttributeError: 'KinovaRobotEnv' object has no attribute 'sim'

