[SessionManager] Connection timeout detected (1606415542.7062154)
[ERROR 2020-11-26 13:32:24,080] function_runner.py: 254  Runner Thread raised error.
Traceback (most recent call last):
  File "/home/avandekl/miniconda3/lib/python3.8/site-packages/ray/tune/function_runner.py", line 248, in run
    self._entrypoint()
  File "/home/avandekl/miniconda3/lib/python3.8/site-packages/ray/tune/function_runner.py", line 315, in entrypoint
    return self._trainable_func(self.config, self._status_reporter,
  File "/home/avandekl/miniconda3/lib/python3.8/site-packages/ray/tune/function_runner.py", line 575, in _trainable_func
    output = fn()
  File "run.py", line 13, in trainable
    experiment.train()
  File "/home/avandekl/Documents/gbrlfi/train.py", line 204, in train
    next_obs_dict, reward, done, info = self.env.step(action)
  File "/home/avandekl/Documents/gbrlfi/wrappers.py", line 235, in step
    obs, reward, done, info = self.env.step(action)
  File "/home/avandekl/Documents/gbrlfi/wrappers.py", line 156, in step
    obs_dict, rew, done, info = self.env.step(act)
  File "/home/avandekl/miniconda3/lib/python3.8/site-packages/gym/core.py", line 234, in step
    return self.env.step(action)
  File "/home/avandekl/miniconda3/lib/python3.8/site-packages/gym/wrappers/time_limit.py", line 16, in step
    observation, reward, done, info = self.env.step(action)
  File "/home/avandekl/Documents/gbrlfi/kinova.py", line 114, in step
    obs_dict = self._get_obs_dict()
  File "/home/avandekl/Documents/gbrlfi/kinova.py", line 196, in _get_obs_dict
    observation = self._get_obs()
  File "/home/avandekl/Documents/gbrlfi/kinova.py", line 185, in _get_obs
    feedback = self.base_cyclic.RefreshFeedback()
  File "/home/avandekl/miniconda3/lib/python3.8/site-packages/kortex_api/autogen/client_stubs/BaseCyclicClientRpc.py", line 68, in RefreshFeedback
    result = future.result(options.getTimeoutInSecond())
  File "/home/avandekl/miniconda3/lib/python3.8/concurrent/futures/_base.py", line 441, in result
    raise TimeoutError()
concurrent.futures._base.TimeoutError
Exception in thread Thread-2:
Traceback (most recent call last):
  File "/home/avandekl/miniconda3/lib/python3.8/threading.py", line 932, in _bootstrap_inner
    self.run()
  File "/home/avandekl/miniconda3/lib/python3.8/site-packages/ray/tune/function_runner.py", line 267, in run
    raise e
  File "/home/avandekl/miniconda3/lib/python3.8/site-packages/ray/tune/function_runner.py", line 248, in run
    self._entrypoint()
  File "/home/avandekl/miniconda3/lib/python3.8/site-packages/ray/tune/function_runner.py", line 315, in entrypoint
    return self._trainable_func(self.config, self._status_reporter,
  File "/home/avandekl/miniconda3/lib/python3.8/site-packages/ray/tune/function_runner.py", line 575, in _trainable_func
    output = fn()
  File "run.py", line 13, in trainable
    experiment.train()
  File "/home/avandekl/Documents/gbrlfi/train.py", line 204, in train
    next_obs_dict, reward, done, info = self.env.step(action)
  File "/home/avandekl/Documents/gbrlfi/wrappers.py", line 235, in step
    obs, reward, done, info = self.env.step(action)
  File "/home/avandekl/Documents/gbrlfi/wrappers.py", line 156, in step
    obs_dict, rew, done, info = self.env.step(act)
  File "/home/avandekl/miniconda3/lib/python3.8/site-packages/gym/core.py", line 234, in step
    return self.env.step(action)
  File "/home/avandekl/miniconda3/lib/python3.8/site-packages/gym/wrappers/time_limit.py", line 16, in step
    observation, reward, done, info = self.env.step(action)
  File "/home/avandekl/Documents/gbrlfi/kinova.py", line 114, in step
    obs_dict = self._get_obs_dict()
  File "/home/avandekl/Documents/gbrlfi/kinova.py", line 196, in _get_obs_dict
    observation = self._get_obs()
  File "/home/avandekl/Documents/gbrlfi/kinova.py", line 185, in _get_obs
    feedback = self.base_cyclic.RefreshFeedback()
  File "/home/avandekl/miniconda3/lib/python3.8/site-packages/kortex_api/autogen/client_stubs/BaseCyclicClientRpc.py", line 68, in RefreshFeedback
    result = future.result(options.getTimeoutInSecond())
  File "/home/avandekl/miniconda3/lib/python3.8/concurrent/futures/_base.py", line 441, in result
    raise TimeoutError()
concurrent.futures._base.TimeoutError
